[2024-06-15T13:30:13.651+0000] {taskinstance.py:1157} INFO - Dependencies all met for dep_context=non-requeueable deps ti=<TaskInstance: minio_upload_dag.crawl_data_task manual__2024-06-15T13:22:58.999332+00:00 [queued]>
[2024-06-15T13:30:13.662+0000] {taskinstance.py:1157} INFO - Dependencies all met for dep_context=requeueable deps ti=<TaskInstance: minio_upload_dag.crawl_data_task manual__2024-06-15T13:22:58.999332+00:00 [queued]>
[2024-06-15T13:30:13.664+0000] {taskinstance.py:1359} INFO - Starting attempt 2 of 2
[2024-06-15T13:30:13.680+0000] {taskinstance.py:1380} INFO - Executing <Task(PythonOperator): crawl_data_task> on 2024-06-15 13:22:58.999332+00:00
[2024-06-15T13:30:13.695+0000] {standard_task_runner.py:57} INFO - Started process 2717 to run task
[2024-06-15T13:30:13.710+0000] {standard_task_runner.py:84} INFO - Running: ['***', 'tasks', 'run', 'minio_upload_dag', 'crawl_data_task', 'manual__2024-06-15T13:22:58.999332+00:00', '--job-id', '60', '--raw', '--subdir', 'DAGS_FOLDER/Upload_minio.py', '--cfg-path', '/tmp/tmp39acyn58']
[2024-06-15T13:30:13.799+0000] {standard_task_runner.py:85} INFO - Job 60: Subtask crawl_data_task
[2024-06-15T13:30:14.396+0000] {task_command.py:415} INFO - Running <TaskInstance: minio_upload_dag.crawl_data_task manual__2024-06-15T13:22:58.999332+00:00 [running]> on host 3d7c41a4db76
[2024-06-15T13:30:14.666+0000] {taskinstance.py:1660} INFO - Exporting env vars: AIRFLOW_CTX_DAG_OWNER='***' AIRFLOW_CTX_DAG_ID='minio_upload_dag' AIRFLOW_CTX_TASK_ID='crawl_data_task' AIRFLOW_CTX_EXECUTION_DATE='2024-06-15T13:22:58.999332+00:00' AIRFLOW_CTX_TRY_NUMBER='2' AIRFLOW_CTX_DAG_RUN_ID='manual__2024-06-15T13:22:58.999332+00:00'
[2024-06-15T13:32:16.785+0000] {taskinstance.py:1935} ERROR - Task failed with exception
Traceback (most recent call last):
  File "/home/airflow/.local/lib/python3.9/site-packages/urllib3/connectionpool.py", line 714, in urlopen
    httplib_response = self._make_request(
  File "/home/airflow/.local/lib/python3.9/site-packages/urllib3/connectionpool.py", line 466, in _make_request
    six.raise_from(e, None)
  File "<string>", line 3, in raise_from
  File "/home/airflow/.local/lib/python3.9/site-packages/urllib3/connectionpool.py", line 461, in _make_request
    httplib_response = conn.getresponse()
  File "/usr/local/lib/python3.9/http/client.py", line 1377, in getresponse
    response.begin()
  File "/usr/local/lib/python3.9/http/client.py", line 320, in begin
    version, status, reason = self._read_status()
  File "/usr/local/lib/python3.9/http/client.py", line 289, in _read_status
    raise RemoteDisconnected("Remote end closed connection without"
http.client.RemoteDisconnected: Remote end closed connection without response

During handling of the above exception, another exception occurred:

Traceback (most recent call last):
  File "/home/airflow/.local/lib/python3.9/site-packages/requests/adapters.py", line 486, in send
    resp = conn.urlopen(
  File "/home/airflow/.local/lib/python3.9/site-packages/urllib3/connectionpool.py", line 798, in urlopen
    retries = retries.increment(
  File "/home/airflow/.local/lib/python3.9/site-packages/urllib3/util/retry.py", line 550, in increment
    raise six.reraise(type(error), error, _stacktrace)
  File "/home/airflow/.local/lib/python3.9/site-packages/urllib3/packages/six.py", line 769, in reraise
    raise value.with_traceback(tb)
  File "/home/airflow/.local/lib/python3.9/site-packages/urllib3/connectionpool.py", line 714, in urlopen
    httplib_response = self._make_request(
  File "/home/airflow/.local/lib/python3.9/site-packages/urllib3/connectionpool.py", line 466, in _make_request
    six.raise_from(e, None)
  File "<string>", line 3, in raise_from
  File "/home/airflow/.local/lib/python3.9/site-packages/urllib3/connectionpool.py", line 461, in _make_request
    httplib_response = conn.getresponse()
  File "/usr/local/lib/python3.9/http/client.py", line 1377, in getresponse
    response.begin()
  File "/usr/local/lib/python3.9/http/client.py", line 320, in begin
    version, status, reason = self._read_status()
  File "/usr/local/lib/python3.9/http/client.py", line 289, in _read_status
    raise RemoteDisconnected("Remote end closed connection without"
urllib3.exceptions.ProtocolError: ('Connection aborted.', RemoteDisconnected('Remote end closed connection without response'))

During handling of the above exception, another exception occurred:

Traceback (most recent call last):
  File "/home/airflow/.local/lib/python3.9/site-packages/airflow/operators/python.py", line 192, in execute
    return_value = self.execute_callable()
  File "/home/airflow/.local/lib/python3.9/site-packages/airflow/operators/python.py", line 209, in execute_callable
    return self.python_callable(*self.op_args, **self.op_kwargs)
  File "/opt/airflow/dags/Upload_minio.py", line 33, in crawl_data
    CrawlData.get_full_list_stock_price()
  File "/opt/airflow/code/CrawlData.py", line 31, in get_full_list_stock_price
    temp_df=pd.DataFrame(stock_historical_data(symbol=company, start_date=current_day(), end_date=current_day(), resolution="1D", type="stock", beautify=True, decor=False, source='DNSE'))
  File "/home/airflow/.local/lib/python3.9/site-packages/vnstock/technical.py", line 24, in stock_historical_data
    df = ohlc_data(symbol, start_date, end_date, resolution, type, headers=entrade_headers)
  File "/home/airflow/.local/lib/python3.9/site-packages/vnstock/technical.py", line 170, in ohlc_data
    response = requests.request("GET", url, headers=headers)
  File "/home/airflow/.local/lib/python3.9/site-packages/requests/api.py", line 59, in request
    return session.request(method=method, url=url, **kwargs)
  File "/home/airflow/.local/lib/python3.9/site-packages/requests/sessions.py", line 589, in request
    resp = self.send(prep, **send_kwargs)
  File "/home/airflow/.local/lib/python3.9/site-packages/requests/sessions.py", line 703, in send
    r = adapter.send(request, **kwargs)
  File "/home/airflow/.local/lib/python3.9/site-packages/requests/adapters.py", line 501, in send
    raise ConnectionError(err, request=request)
requests.exceptions.ConnectionError: ('Connection aborted.', RemoteDisconnected('Remote end closed connection without response'))
[2024-06-15T13:32:25.287+0000] {taskinstance.py:1398} INFO - Marking task as FAILED. dag_id=minio_upload_dag, task_id=crawl_data_task, execution_date=20240615T132258, start_date=20240615T133013, end_date=20240615T133225
[2024-06-15T13:32:25.835+0000] {standard_task_runner.py:104} ERROR - Failed to execute job 60 for task crawl_data_task (('Connection aborted.', RemoteDisconnected('Remote end closed connection without response')); 2717)
[2024-06-15T13:32:26.379+0000] {local_task_job_runner.py:228} INFO - Task exited with return code 1
[2024-06-15T13:32:26.831+0000] {taskinstance.py:2776} INFO - 0 downstream tasks scheduled from follow-on schedule check
