[2024-06-12T09:07:33.455+0000] {local_task_job_runner.py:120} INFO - ::group::Pre task execution logs
[2024-06-12T09:07:33.977+0000] {taskinstance.py:2076} INFO - Dependencies all met for dep_context=non-requeueable deps ti=<TaskInstance: minio_upload_dag.upload_file_to_minio scheduled__2023-01-08T00:00:00+00:00 [queued]>
[2024-06-12T09:07:34.269+0000] {taskinstance.py:2076} INFO - Dependencies all met for dep_context=requeueable deps ti=<TaskInstance: minio_upload_dag.upload_file_to_minio scheduled__2023-01-08T00:00:00+00:00 [queued]>
[2024-06-12T09:07:34.278+0000] {taskinstance.py:2306} INFO - Starting attempt 1 of 2
[2024-06-12T09:07:35.003+0000] {taskinstance.py:2330} INFO - Executing <Task(PythonOperator): upload_file_to_minio> on 2023-01-08 00:00:00+00:00
[2024-06-12T09:07:35.181+0000] {standard_task_runner.py:90} INFO - Running: ['***', 'tasks', 'run', 'minio_upload_dag', 'upload_file_to_minio', 'scheduled__2023-01-08T00:00:00+00:00', '--job-id', '9', '--raw', '--subdir', 'DAGS_FOLDER/Upload_minio.py', '--cfg-path', '/tmp/tmpg3rs9zhs']
[2024-06-12T09:07:35.324+0000] {standard_task_runner.py:91} INFO - Job 9: Subtask upload_file_to_minio
[2024-06-12T09:07:35.484+0000] {logging_mixin.py:188} WARNING - /home/***/.local/lib/python3.12/site-packages/***/task/task_runner/standard_task_runner.py:61 DeprecationWarning: This process (pid=1224) is multi-threaded, use of fork() may lead to deadlocks in the child.
[2024-06-12T09:07:35.757+0000] {standard_task_runner.py:63} INFO - Started process 1239 to run task
[2024-06-12T09:07:43.463+0000] {task_command.py:426} INFO - Running <TaskInstance: minio_upload_dag.upload_file_to_minio scheduled__2023-01-08T00:00:00+00:00 [running]> on host aa419cbec97c
[2024-06-12T09:07:45.418+0000] {taskinstance.py:2648} INFO - Exporting env vars: AIRFLOW_CTX_DAG_OWNER='***' AIRFLOW_CTX_DAG_ID='minio_upload_dag' AIRFLOW_CTX_TASK_ID='upload_file_to_minio' AIRFLOW_CTX_EXECUTION_DATE='2023-01-08T00:00:00+00:00' AIRFLOW_CTX_TRY_NUMBER='1' AIRFLOW_CTX_DAG_RUN_ID='scheduled__2023-01-08T00:00:00+00:00'
[2024-06-12T09:07:45.444+0000] {taskinstance.py:430} INFO - ::endgroup::
[2024-06-12T09:07:46.101+0000] {base_aws.py:587} WARNING - Unable to find AWS Connection ID 'minio_conn', switching to empty.
[2024-06-12T09:07:46.142+0000] {base_aws.py:164} INFO - No connection ID provided. Fallback on boto3 credential strategy (region_name=None). See: https://boto3.amazonaws.com/v1/documentation/api/latest/guide/configuration.html
[2024-06-12T09:08:09.342+0000] {taskinstance.py:441} INFO - ::group::Post task execution logs
[2024-06-12T09:08:09.708+0000] {taskinstance.py:2905} ERROR - Task failed with exception
Traceback (most recent call last):
  File "/home/airflow/.local/lib/python3.12/site-packages/airflow/models/taskinstance.py", line 465, in _execute_task
    result = _execute_callable(context=context, **execute_callable_kwargs)
             ^^^^^^^^^^^^^^^^^^^^^^^^^^^^^^^^^^^^^^^^^^^^^^^^^^^^^^^^^^^^^
  File "/home/airflow/.local/lib/python3.12/site-packages/airflow/models/taskinstance.py", line 432, in _execute_callable
    return execute_callable(context=context, **execute_callable_kwargs)
           ^^^^^^^^^^^^^^^^^^^^^^^^^^^^^^^^^^^^^^^^^^^^^^^^^^^^^^^^^^^^
  File "/home/airflow/.local/lib/python3.12/site-packages/airflow/models/baseoperator.py", line 401, in wrapper
    return func(self, *args, **kwargs)
           ^^^^^^^^^^^^^^^^^^^^^^^^^^^
  File "/home/airflow/.local/lib/python3.12/site-packages/airflow/operators/python.py", line 235, in execute
    return_value = self.execute_callable()
                   ^^^^^^^^^^^^^^^^^^^^^^^
  File "/home/airflow/.local/lib/python3.12/site-packages/airflow/operators/python.py", line 252, in execute_callable
    return self.python_callable(*self.op_args, **self.op_kwargs)
           ^^^^^^^^^^^^^^^^^^^^^^^^^^^^^^^^^^^^^^^^^^^^^^^^^^^^^
  File "/opt/airflow/dags/Upload_minio.py", line 26, in upload_to_minio
    hook.load_file(filename=file_path, key=object_name, bucket_name=bucket_name, replace=True)
  File "/home/airflow/.local/lib/python3.12/site-packages/airflow/providers/amazon/aws/hooks/s3.py", line 135, in wrapper
    return func(*bound_args.args, **bound_args.kwargs)
           ^^^^^^^^^^^^^^^^^^^^^^^^^^^^^^^^^^^^^^^^^^^
  File "/home/airflow/.local/lib/python3.12/site-packages/airflow/providers/amazon/aws/hooks/s3.py", line 89, in wrapper
    return func(*bound_args.args, **bound_args.kwargs)
           ^^^^^^^^^^^^^^^^^^^^^^^^^^^^^^^^^^^^^^^^^^^
  File "/home/airflow/.local/lib/python3.12/site-packages/airflow/providers/amazon/aws/hooks/s3.py", line 1098, in load_file
    client.upload_file(filename, bucket_name, key, ExtraArgs=extra_args, Config=self.transfer_config)
  File "/home/airflow/.local/lib/python3.12/site-packages/boto3/s3/inject.py", line 145, in upload_file
    return transfer.upload_file(
           ^^^^^^^^^^^^^^^^^^^^^
  File "/home/airflow/.local/lib/python3.12/site-packages/boto3/s3/transfer.py", line 371, in upload_file
    future.result()
  File "/home/airflow/.local/lib/python3.12/site-packages/s3transfer/futures.py", line 103, in result
    return self._coordinator.result()
           ^^^^^^^^^^^^^^^^^^^^^^^^^^
  File "/home/airflow/.local/lib/python3.12/site-packages/s3transfer/futures.py", line 266, in result
    raise self._exception
  File "/home/airflow/.local/lib/python3.12/site-packages/s3transfer/tasks.py", line 269, in _main
    self._submit(transfer_future=transfer_future, **kwargs)
  File "/home/airflow/.local/lib/python3.12/site-packages/s3transfer/upload.py", line 591, in _submit
    upload_input_manager.provide_transfer_size(transfer_future)
  File "/home/airflow/.local/lib/python3.12/site-packages/s3transfer/upload.py", line 244, in provide_transfer_size
    self._osutil.get_file_size(transfer_future.meta.call_args.fileobj)
  File "/home/airflow/.local/lib/python3.12/site-packages/s3transfer/utils.py", line 256, in get_file_size
    return os.path.getsize(filename)
           ^^^^^^^^^^^^^^^^^^^^^^^^^
  File "<frozen genericpath>", line 62, in getsize
FileNotFoundError: [Errno 2] No such file or directory: '/Users/chauminhkhai/VDTStockProject/stockprice.csv'
[2024-06-12T09:08:10.070+0000] {taskinstance.py:1206} INFO - Marking task as UP_FOR_RETRY. dag_id=minio_upload_dag, task_id=upload_file_to_minio, run_id=scheduled__2023-01-08T00:00:00+00:00, execution_date=20230108T000000, start_date=20240612T090734, end_date=20240612T090810
[2024-06-12T09:08:10.302+0000] {standard_task_runner.py:110} ERROR - Failed to execute job 9 for task upload_file_to_minio ([Errno 2] No such file or directory: '/Users/chauminhkhai/VDTStockProject/stockprice.csv'; 1239)
[2024-06-12T09:08:10.443+0000] {local_task_job_runner.py:240} INFO - Task exited with return code 1
[2024-06-12T09:08:11.057+0000] {taskinstance.py:3503} INFO - 0 downstream tasks scheduled from follow-on schedule check
[2024-06-12T09:08:11.183+0000] {local_task_job_runner.py:222} INFO - ::endgroup::
