[2024-06-15T13:37:08.067+0000] {taskinstance.py:1157} INFO - Dependencies all met for dep_context=non-requeueable deps ti=<TaskInstance: minio_upload_dag.upload_file_to_minio_0 manual__2024-06-15T13:36:58.403241+00:00 [queued]>
[2024-06-15T13:37:08.082+0000] {taskinstance.py:1157} INFO - Dependencies all met for dep_context=requeueable deps ti=<TaskInstance: minio_upload_dag.upload_file_to_minio_0 manual__2024-06-15T13:36:58.403241+00:00 [queued]>
[2024-06-15T13:37:08.085+0000] {taskinstance.py:1359} INFO - Starting attempt 1 of 2
[2024-06-15T13:37:08.153+0000] {taskinstance.py:1380} INFO - Executing <Task(PythonOperator): upload_file_to_minio_0> on 2024-06-15 13:36:58.403241+00:00
[2024-06-15T13:37:08.238+0000] {standard_task_runner.py:57} INFO - Started process 2919 to run task
[2024-06-15T13:37:08.358+0000] {standard_task_runner.py:84} INFO - Running: ['***', 'tasks', 'run', 'minio_upload_dag', 'upload_file_to_minio_0', 'manual__2024-06-15T13:36:58.403241+00:00', '--job-id', '65', '--raw', '--subdir', 'DAGS_FOLDER/Upload_minio.py', '--cfg-path', '/tmp/tmpix4ymz0v']
[2024-06-15T13:37:08.537+0000] {standard_task_runner.py:85} INFO - Job 65: Subtask upload_file_to_minio_0
[2024-06-15T13:37:09.928+0000] {task_command.py:415} INFO - Running <TaskInstance: minio_upload_dag.upload_file_to_minio_0 manual__2024-06-15T13:36:58.403241+00:00 [running]> on host 3d7c41a4db76
[2024-06-15T13:37:10.112+0000] {taskinstance.py:1660} INFO - Exporting env vars: AIRFLOW_CTX_DAG_OWNER='***' AIRFLOW_CTX_DAG_ID='minio_upload_dag' AIRFLOW_CTX_TASK_ID='upload_file_to_minio_0' AIRFLOW_CTX_EXECUTION_DATE='2024-06-15T13:36:58.403241+00:00' AIRFLOW_CTX_TRY_NUMBER='1' AIRFLOW_CTX_DAG_RUN_ID='manual__2024-06-15T13:36:58.403241+00:00'
[2024-06-15T13:37:10.144+0000] {base.py:73} INFO - Using connection ID 'minio_s3_connection' for task execution.
[2024-06-15T13:37:14.386+0000] {taskinstance.py:1935} ERROR - Task failed with exception
Traceback (most recent call last):
  File "/home/airflow/.local/lib/python3.9/site-packages/airflow/operators/python.py", line 192, in execute
    return_value = self.execute_callable()
  File "/home/airflow/.local/lib/python3.9/site-packages/airflow/operators/python.py", line 209, in execute_callable
    return self.python_callable(*self.op_args, **self.op_kwargs)
  File "/opt/airflow/dags/Upload_minio.py", line 31, in upload_to_minio
    hook.load_file(filename=file_path, key=object_name, bucket_name=bucket_name, replace=True)
  File "/home/airflow/.local/lib/python3.9/site-packages/airflow/providers/amazon/aws/hooks/s3.py", line 138, in wrapper
    return func(*bound_args.args, **bound_args.kwargs)
  File "/home/airflow/.local/lib/python3.9/site-packages/airflow/providers/amazon/aws/hooks/s3.py", line 92, in wrapper
    return func(*bound_args.args, **bound_args.kwargs)
  File "/home/airflow/.local/lib/python3.9/site-packages/airflow/providers/amazon/aws/hooks/s3.py", line 1074, in load_file
    client.upload_file(filename, bucket_name, key, ExtraArgs=extra_args, Config=self.transfer_config)
  File "/home/airflow/.local/lib/python3.9/site-packages/boto3/s3/inject.py", line 143, in upload_file
    return transfer.upload_file(
  File "/home/airflow/.local/lib/python3.9/site-packages/boto3/s3/transfer.py", line 292, in upload_file
    future.result()
  File "/home/airflow/.local/lib/python3.9/site-packages/s3transfer/futures.py", line 103, in result
    return self._coordinator.result()
  File "/home/airflow/.local/lib/python3.9/site-packages/s3transfer/futures.py", line 266, in result
    raise self._exception
  File "/home/airflow/.local/lib/python3.9/site-packages/s3transfer/tasks.py", line 139, in __call__
    return self._execute_main(kwargs)
  File "/home/airflow/.local/lib/python3.9/site-packages/s3transfer/tasks.py", line 162, in _execute_main
    return_value = self._main(**kwargs)
  File "/home/airflow/.local/lib/python3.9/site-packages/s3transfer/upload.py", line 758, in _main
    client.put_object(Bucket=bucket, Key=key, Body=body, **extra_args)
  File "/home/airflow/.local/lib/python3.9/site-packages/botocore/client.py", line 535, in _api_call
    return self._make_api_call(operation_name, kwargs)
  File "/home/airflow/.local/lib/python3.9/site-packages/botocore/client.py", line 963, in _make_api_call
    http, parsed_response = self._make_request(
  File "/home/airflow/.local/lib/python3.9/site-packages/botocore/client.py", line 986, in _make_request
    return self._endpoint.make_request(operation_model, request_dict)
  File "/home/airflow/.local/lib/python3.9/site-packages/botocore/endpoint.py", line 119, in make_request
    return self._send_request(request_dict, operation_model)
  File "/home/airflow/.local/lib/python3.9/site-packages/botocore/endpoint.py", line 198, in _send_request
    request = self.create_request(request_dict, operation_model)
  File "/home/airflow/.local/lib/python3.9/site-packages/botocore/endpoint.py", line 134, in create_request
    self._event_emitter.emit(
  File "/home/airflow/.local/lib/python3.9/site-packages/botocore/hooks.py", line 412, in emit
    return self._emitter.emit(aliased_event_name, **kwargs)
  File "/home/airflow/.local/lib/python3.9/site-packages/botocore/hooks.py", line 256, in emit
    return self._emit(event_name, kwargs)
  File "/home/airflow/.local/lib/python3.9/site-packages/botocore/hooks.py", line 239, in _emit
    response = handler(**kwargs)
  File "/home/airflow/.local/lib/python3.9/site-packages/botocore/signers.py", line 105, in handler
    return self.sign(operation_name, request)
  File "/home/airflow/.local/lib/python3.9/site-packages/botocore/signers.py", line 189, in sign
    auth.add_auth(request)
  File "/home/airflow/.local/lib/python3.9/site-packages/botocore/auth.py", line 418, in add_auth
    raise NoCredentialsError()
botocore.exceptions.NoCredentialsError: Unable to locate credentials
[2024-06-15T13:37:14.456+0000] {taskinstance.py:1398} INFO - Marking task as UP_FOR_RETRY. dag_id=minio_upload_dag, task_id=upload_file_to_minio_0, execution_date=20240615T133658, start_date=20240615T133708, end_date=20240615T133714
[2024-06-15T13:37:14.495+0000] {standard_task_runner.py:104} ERROR - Failed to execute job 65 for task upload_file_to_minio_0 (Unable to locate credentials; 2919)
[2024-06-15T13:37:14.535+0000] {local_task_job_runner.py:228} INFO - Task exited with return code 1
[2024-06-15T13:37:14.637+0000] {taskinstance.py:2776} INFO - 0 downstream tasks scheduled from follow-on schedule check
