[2024-06-13T19:46:48.124+0000] {local_task_job_runner.py:120} INFO - ::group::Pre task execution logs
[2024-06-13T19:46:48.134+0000] {taskinstance.py:2076} INFO - Dependencies all met for dep_context=non-requeueable deps ti=<TaskInstance: minio_upload_dag.upload_file_to_minio_0 manual__2024-06-13T19:44:52.237697+00:00 [queued]>
[2024-06-13T19:46:48.140+0000] {taskinstance.py:2076} INFO - Dependencies all met for dep_context=requeueable deps ti=<TaskInstance: minio_upload_dag.upload_file_to_minio_0 manual__2024-06-13T19:44:52.237697+00:00 [queued]>
[2024-06-13T19:46:48.141+0000] {taskinstance.py:2306} INFO - Starting attempt 2 of 2
[2024-06-13T19:46:48.149+0000] {taskinstance.py:2330} INFO - Executing <Task(PythonOperator): upload_file_to_minio_0> on 2024-06-13 19:44:52.237697+00:00
[2024-06-13T19:46:48.161+0000] {standard_task_runner.py:63} INFO - Started process 947 to run task
[2024-06-13T19:46:48.164+0000] {standard_task_runner.py:90} INFO - Running: ['***', 'tasks', 'run', 'minio_upload_dag', 'upload_file_to_minio_0', 'manual__2024-06-13T19:44:52.237697+00:00', '--job-id', '65', '--raw', '--subdir', 'DAGS_FOLDER/Upload_minio.py', '--cfg-path', '/tmp/tmpbgqqt65n']
[2024-06-13T19:46:48.166+0000] {standard_task_runner.py:91} INFO - Job 65: Subtask upload_file_to_minio_0
[2024-06-13T19:46:48.222+0000] {task_command.py:426} INFO - Running <TaskInstance: minio_upload_dag.upload_file_to_minio_0 manual__2024-06-13T19:44:52.237697+00:00 [running]> on host 40bbaf5cd7cf
[2024-06-13T19:46:48.288+0000] {taskinstance.py:2648} INFO - Exporting env vars: AIRFLOW_CTX_DAG_OWNER='***' AIRFLOW_CTX_DAG_ID='minio_upload_dag' AIRFLOW_CTX_TASK_ID='upload_file_to_minio_0' AIRFLOW_CTX_EXECUTION_DATE='2024-06-13T19:44:52.237697+00:00' AIRFLOW_CTX_TRY_NUMBER='2' AIRFLOW_CTX_DAG_RUN_ID='manual__2024-06-13T19:44:52.237697+00:00'
[2024-06-13T19:46:48.290+0000] {taskinstance.py:430} INFO - ::endgroup::
[2024-06-13T19:46:48.304+0000] {base.py:84} INFO - Using connection ID 'minio_s3_connection' for task execution.
[2024-06-13T19:46:49.073+0000] {taskinstance.py:441} INFO - ::group::Post task execution logs
[2024-06-13T19:46:49.078+0000] {taskinstance.py:2905} ERROR - Task failed with exception
Traceback (most recent call last):
  File "/home/airflow/.local/lib/python3.11/site-packages/airflow/models/taskinstance.py", line 465, in _execute_task
    result = _execute_callable(context=context, **execute_callable_kwargs)
             ^^^^^^^^^^^^^^^^^^^^^^^^^^^^^^^^^^^^^^^^^^^^^^^^^^^^^^^^^^^^^
  File "/home/airflow/.local/lib/python3.11/site-packages/airflow/models/taskinstance.py", line 432, in _execute_callable
    return execute_callable(context=context, **execute_callable_kwargs)
           ^^^^^^^^^^^^^^^^^^^^^^^^^^^^^^^^^^^^^^^^^^^^^^^^^^^^^^^^^^^^
  File "/home/airflow/.local/lib/python3.11/site-packages/airflow/models/baseoperator.py", line 401, in wrapper
    return func(self, *args, **kwargs)
           ^^^^^^^^^^^^^^^^^^^^^^^^^^^
  File "/home/airflow/.local/lib/python3.11/site-packages/airflow/operators/python.py", line 235, in execute
    return_value = self.execute_callable()
                   ^^^^^^^^^^^^^^^^^^^^^^^
  File "/home/airflow/.local/lib/python3.11/site-packages/airflow/operators/python.py", line 252, in execute_callable
    return self.python_callable(*self.op_args, **self.op_kwargs)
           ^^^^^^^^^^^^^^^^^^^^^^^^^^^^^^^^^^^^^^^^^^^^^^^^^^^^^
  File "/opt/airflow/dags/Upload_minio.py", line 31, in upload_to_minio
    hook.load_file(filename=file_path, key=object_name, bucket_name=bucket_name, replace=True)
  File "/home/airflow/.local/lib/python3.11/site-packages/airflow/providers/amazon/aws/hooks/s3.py", line 135, in wrapper
    return func(*bound_args.args, **bound_args.kwargs)
           ^^^^^^^^^^^^^^^^^^^^^^^^^^^^^^^^^^^^^^^^^^^
  File "/home/airflow/.local/lib/python3.11/site-packages/airflow/providers/amazon/aws/hooks/s3.py", line 89, in wrapper
    return func(*bound_args.args, **bound_args.kwargs)
           ^^^^^^^^^^^^^^^^^^^^^^^^^^^^^^^^^^^^^^^^^^^
  File "/home/airflow/.local/lib/python3.11/site-packages/airflow/providers/amazon/aws/hooks/s3.py", line 1098, in load_file
    client.upload_file(filename, bucket_name, key, ExtraArgs=extra_args, Config=self.transfer_config)
  File "/home/airflow/.local/lib/python3.11/site-packages/boto3/s3/inject.py", line 145, in upload_file
    return transfer.upload_file(
           ^^^^^^^^^^^^^^^^^^^^^
  File "/home/airflow/.local/lib/python3.11/site-packages/boto3/s3/transfer.py", line 371, in upload_file
    future.result()
  File "/home/airflow/.local/lib/python3.11/site-packages/s3transfer/futures.py", line 103, in result
    return self._coordinator.result()
           ^^^^^^^^^^^^^^^^^^^^^^^^^^
  File "/home/airflow/.local/lib/python3.11/site-packages/s3transfer/futures.py", line 266, in result
    raise self._exception
  File "/home/airflow/.local/lib/python3.11/site-packages/s3transfer/tasks.py", line 139, in __call__
    return self._execute_main(kwargs)
           ^^^^^^^^^^^^^^^^^^^^^^^^^^
  File "/home/airflow/.local/lib/python3.11/site-packages/s3transfer/tasks.py", line 162, in _execute_main
    return_value = self._main(**kwargs)
                   ^^^^^^^^^^^^^^^^^^^^
  File "/home/airflow/.local/lib/python3.11/site-packages/s3transfer/upload.py", line 764, in _main
    client.put_object(Bucket=bucket, Key=key, Body=body, **extra_args)
  File "/home/airflow/.local/lib/python3.11/site-packages/botocore/client.py", line 565, in _api_call
    return self._make_api_call(operation_name, kwargs)
           ^^^^^^^^^^^^^^^^^^^^^^^^^^^^^^^^^^^^^^^^^^^
  File "/home/airflow/.local/lib/python3.11/site-packages/botocore/client.py", line 1001, in _make_api_call
    http, parsed_response = self._make_request(
                            ^^^^^^^^^^^^^^^^^^^
  File "/home/airflow/.local/lib/python3.11/site-packages/botocore/client.py", line 1027, in _make_request
    return self._endpoint.make_request(operation_model, request_dict)
           ^^^^^^^^^^^^^^^^^^^^^^^^^^^^^^^^^^^^^^^^^^^^^^^^^^^^^^^^^^
  File "/home/airflow/.local/lib/python3.11/site-packages/botocore/endpoint.py", line 119, in make_request
    return self._send_request(request_dict, operation_model)
           ^^^^^^^^^^^^^^^^^^^^^^^^^^^^^^^^^^^^^^^^^^^^^^^^^
  File "/home/airflow/.local/lib/python3.11/site-packages/botocore/endpoint.py", line 198, in _send_request
    request = self.create_request(request_dict, operation_model)
              ^^^^^^^^^^^^^^^^^^^^^^^^^^^^^^^^^^^^^^^^^^^^^^^^^^
  File "/home/airflow/.local/lib/python3.11/site-packages/botocore/endpoint.py", line 134, in create_request
    self._event_emitter.emit(
  File "/home/airflow/.local/lib/python3.11/site-packages/botocore/hooks.py", line 412, in emit
    return self._emitter.emit(aliased_event_name, **kwargs)
           ^^^^^^^^^^^^^^^^^^^^^^^^^^^^^^^^^^^^^^^^^^^^^^^^
  File "/home/airflow/.local/lib/python3.11/site-packages/botocore/hooks.py", line 256, in emit
    return self._emit(event_name, kwargs)
           ^^^^^^^^^^^^^^^^^^^^^^^^^^^^^^
  File "/home/airflow/.local/lib/python3.11/site-packages/botocore/hooks.py", line 239, in _emit
    response = handler(**kwargs)
               ^^^^^^^^^^^^^^^^^
  File "/home/airflow/.local/lib/python3.11/site-packages/botocore/signers.py", line 105, in handler
    return self.sign(operation_name, request)
           ^^^^^^^^^^^^^^^^^^^^^^^^^^^^^^^^^^
  File "/home/airflow/.local/lib/python3.11/site-packages/botocore/signers.py", line 199, in sign
    auth.add_auth(request)
  File "/home/airflow/.local/lib/python3.11/site-packages/botocore/auth.py", line 418, in add_auth
    raise NoCredentialsError()
botocore.exceptions.NoCredentialsError: Unable to locate credentials
[2024-06-13T19:46:49.167+0000] {taskinstance.py:1206} INFO - Marking task as FAILED. dag_id=minio_upload_dag, task_id=upload_file_to_minio_0, run_id=manual__2024-06-13T19:44:52.237697+00:00, execution_date=20240613T194452, start_date=20240613T194648, end_date=20240613T194649
[2024-06-13T19:46:49.181+0000] {standard_task_runner.py:110} ERROR - Failed to execute job 65 for task upload_file_to_minio_0 (Unable to locate credentials; 947)
[2024-06-13T19:46:49.242+0000] {local_task_job_runner.py:240} INFO - Task exited with return code 1
[2024-06-13T19:46:49.275+0000] {taskinstance.py:3503} INFO - 0 downstream tasks scheduled from follow-on schedule check
[2024-06-13T19:46:49.279+0000] {local_task_job_runner.py:222} INFO - ::endgroup::
